Badly placed ()'s.
Traceback (most recent call last):
  File "testing.py", line 324, in <module>
    CALI_vs_mu(config)
  File "testing.py", line 312, in CALI_vs_mu
    plt.savefig("./results/CALIvsMU_alg_{}_H={}_MUrange=[{},{}]_initinf={}.png".format(alg,H, config[H][0], config[H][-1], init_inf[0]+1))
  File "/cm/shared/uaapps/anaconda/2019.07/lib/python3.7/site-packages/matplotlib/pyplot.py", line 722, in savefig
    res = fig.savefig(*args, **kwargs)
  File "/cm/shared/uaapps/anaconda/2019.07/lib/python3.7/site-packages/matplotlib/figure.py", line 2180, in savefig
    self.canvas.print_figure(fname, **kwargs)
  File "/cm/shared/uaapps/anaconda/2019.07/lib/python3.7/site-packages/matplotlib/backend_bases.py", line 2082, in print_figure
    **kwargs)
  File "/cm/shared/uaapps/anaconda/2019.07/lib/python3.7/site-packages/matplotlib/backends/backend_agg.py", line 530, in print_png
    cbook.open_file_cm(filename_or_obj, "wb") as fh:
  File "/cm/shared/uaapps/anaconda/2019.07/lib/python3.7/contextlib.py", line 112, in __enter__
    return next(self.gen)
  File "/cm/shared/uaapps/anaconda/2019.07/lib/python3.7/site-packages/matplotlib/cbook/__init__.py", line 447, in open_file_cm
    fh, opened = to_filehandle(path_or_file, mode, True, encoding)
  File "/cm/shared/uaapps/anaconda/2019.07/lib/python3.7/site-packages/matplotlib/cbook/__init__.py", line 432, in to_filehandle
    fh = open(fname, flag, encoding=encoding)
FileNotFoundError: [Errno 2] No such file or directory: './results/CALIvsMU_alg_GBR20_H=0.02_MUrange=[0.0,0.006]_initinf=1.png'
